Workbook

Sheet Daily Report
AA1: RPT DATE: | AD1: =Data!AB4 -> 44201
AB2: RPT NUM: | AD2: =Data!AC4 -> 2
AA3: RIG: | AD3: =Data!R4 -> Frontier Rig 16
B4: WELL/JOB INFORMATION
B5: WELL NAME: | F5: =Data!G4 -> FORGE 16A [78]-32 | Q5: JOB: | T5: =Data!U4 -> DFIT
B6: FIELD: | F6: =Data!H4 -> 0 | Q6: LEASE: | T6: =Data!I4 -> 0
B7: AFE #: | F7: =Data!S4 -> 0 | Q7: API #: | T7: =Data!J4 -> 0
B8: CONTRACTOR: | F8: =Data!Q4 -> Frontier Drilling | Q8: SUPERVISOR: | T8: =Data!AD4 -> D Winkler, L Swearingen, V Welch
B9: TD: | G9: =VALUE(Data!AB7) -> 10987 | J9: TMD | L9: =VALUE(Data!AC7) -> 8559 | O9: TVD | Q9: RIG PHONE: | T9: =Data!AJ4 -> 0
B10: PBTD: | G10: =Data!AE4 -> 0 | J10: TMD | L10: =Data!AF4 -> 0 | O10: TVD | Q10: EMAIL: | T10: =Data!AE7 -> 0
B11: Present Ops: | F11: =AJ11 -> TRIP IN HOLE WITH 3 1/2 DRILL PIPE | AJ11: =Data!AG4 -> TRIP IN HOLE WITH 3 1/2 DRILL PIPE
B12: Next 24 Hours: | F12: =AJ12 -> DRILL OUT CMT, FLOATS AND CIRCULATE OUT SAND | AJ12: =Data!AH4 -> DRILL OUT CMT, FLOATS AND CIRCULATE OUT SAND
B13: COST SUMMARY
B14: COMPLETION AFE AMT: | G14: =Data!T4 -> 0 | L14: DAILY COMP COST: | Q14: =Data!EB4 -> 52569 | V14: CUM COMP COST: | AA14: =Data!EC4 -> 52569
B15: TIME LOG
B16: From | D16: To | F16: Hrs | H16: Phase | L16: Activity | P16: NPT Code | T16: Operations
B17: =Data!DM4 -> 6:00 | D17: =Data!DN4 -> 20:00 | F17: =Data!DO4 -> 14 | H17: =Data!DQ4 -> Well Prep | L17: =Data!DR4 -> Pressure Test BOPs | P17: =Data!DS4 -> 0 | T17: =AI17 -> Weld on wellhead as per API specs Nipple up and test BOPE; Annular 250 psi low / 5,000 psi high Blind rams, pipe rams, choke lines, manifold, floor valves, top drive valves 250 psi low / 10,000 psi high Casing 1,500 psi Accumulator function test | AI17: =Data!DP4 -> Weld on wellhead as per API specs Nipple up and test BOPE; Annular 250 psi low / 5,000 psi high Blind rams, pipe rams, choke lines, manifold, floor valves, top drive valves 250 psi low / 10,000 psi high Casing 1,500 psi Accumulator function test
B18: =Data!DM5 -> 20:00 | D18: =Data!DN5 -> 6:00 | F18: =Data!DO5 -> 10 | H18: =Data!DQ5 -> Well Prep | L18: =Data!DR5 -> Trips | P18: =Data!DS5 -> 0 | T18: =AI18 -> Make up BHA and pick up 3 1/2" drill pipe to 7,300' | AI18: =Data!DP5 -> Make up BHA and pick up 3 1/2" drill pipe to 7,300'
B19: =Data!DM6 -> 0 | D19: =Data!DN6 -> 0 | F19: =Data!DO6 -> 0 | H19: =Data!DQ6 -> 0 | L19: =Data!DR6 -> 0 | P19: =Data!DS6 -> 0 | T19: =AI19 -> 0 | AI19: =Data!DP6 -> 0
B20: =Data!DM7 -> 0 | D20: =Data!DN7 -> 0 | F20: =Data!DO7 -> 0 | H20: =Data!DQ7 -> 0 | L20: =Data!DR7 -> 0 | P20: =Data!DS7 -> 0 | T20: =AI20 -> 0 | AI20: =Data!DP7 -> 0
B21: =Data!DM8 -> 0 | D21: =Data!DN8 -> 0 | F21: =Data!DO8 -> 0 | H21: =Data!DQ8 -> 0 | L21: =Data!DR8 -> 0 | P21: =Data!DS8 -> 0 | T21: =AI21 -> 0 | AI21: =Data!DP8 -> 0
B22: =Data!DM9 -> 0 | D22: =Data!DN9 -> 0 | F22: =Data!DO9 -> 0 | H22: =Data!DQ9 -> 0 | L22: =Data!DR9 -> 0 | P22: =Data!DS9 -> 0 | T22: =AI22 -> 0 | AI22: =Data!DP9 -> 0
B23: =Data!DM10 -> 0 | D23: =Data!DN10 -> 0 | F23: =Data!DO10 -> 0 | H23: =Data!DQ10 -> 0 | L23: =Data!DR10 -> 0 | P23: =Data!DS10 -> 0 | T23: =AI23 -> 0 | AI23: =Data!DP10 -> 0
B24: =Data!DM11 -> 0 | D24: =Data!DN11 -> 0 | F24: =Data!DO11 -> 0 | H24: =Data!DQ11 -> 0 | L24: =Data!DR11 -> 0 | P24: =Data!DS11 -> 0 | T24: =AI24 -> 0 | AI24: =Data!DP11 -> 0
B25: =Data!DM12 -> 0 | D25: =Data!DN12 -> 0 | F25: =Data!DO12 -> 0 | H25: =Data!DQ12 -> 0 | L25: =Data!DR12 -> 0 | P25: =Data!DS12 -> 0 | T25: =AI25 -> 0 | AI25: =Data!DP12 -> 0
B26: =Data!DM13 -> 0 | D26: =Data!DN13 -> 0 | F26: =Data!DO13 -> 0 | H26: =Data!DQ13 -> 0 | L26: =Data!DR13 -> 0 | P26: =Data!DS13 -> 0 | T26: =AI26 -> 0 | AI26: =Data!DP13 -> 0
B27: =Data!DM14 -> 0 | D27: =Data!DN14 -> 0 | F27: =Data!DO14 -> 0 | H27: =Data!DQ14 -> 0 | L27: =Data!DR14 -> 0 | P27: =Data!DS14 -> 0 | T27: =AI27 -> 0 | AI27: =Data!DP14 -> 0
B28: =Data!DM15 -> 0 | D28: =Data!DN15 -> 0 | F28: =Data!DO15 -> 0 | H28: =Data!DQ15 -> 0 | L28: =Data!DR15 -> 0 | P28: =Data!DS15 -> 0 | T28: =AI28 -> 0 | AI28: =Data!DP15 -> 0
... B33: =Data!DM20 -> 0 | D33: =Data!DN20 -> 0 | F33: =Data!DO20 -> 0 | H33: =Data!DQ20 -> 0 | L33: =Data!DR20 -> 0 | P33: =Data!DS20 -> 0 | T33: =AI33 -> 0 | AI33: =Data!DP20 -> 0
B34: Total Hours | F34: =SUM(F17:G33) -> 24
B35: FLUID DATA
B36: Fluid Type | H36: =Data!AR4 -> Mud | P36: Weight | U36: =Data!AS4 -> 9
B37: Fluid Loss Day | H37: =Data!AU4 -> 0 | P37: Fluid Loss Cum | U37: =Data!AV4 -> 0
B38: CONSUMABLES
B39: Type | F39: Daily Rec'd | K39: Daily Used | P39: Daily Net | U39: Cum Rec'd | Y39: Cum Used | AC39: Amount on Hand
B40: =Data!BB4 -> Fuel | F40: =Data!BC4 -> 0 | K40: =Data!BD4 -> 1811 | P40: =Data!BE4 -> -1811 | U40: =Data!BF4 -> 13360 | Y40: =Data!BG4 -> 3137 | AC40: =Data!BH4 -> 10223
B41: =Data!BB5 -> Drill Water | F41: =Data!BC5 -> 314 | K41: =Data!BD5 -> 0 | P41: =Data!BE5 -> 314 | U41: =Data!BF5 -> 314 | Y41: =Data!BG5 -> 0 | AC41: =Data!BH5 -> 314
B42: =Data!BB6 -> 0 | F42: =Data!BC6 -> 0 | K42: =Data!BD6 -> 0 | P42: =Data!BE6 -> 0 | U42: =Data!BF6 -> 0 | Y42: =Data!BG6 -> 0 | AC42: =Data!BH6 -> 0
B43: =Data!BB7 -> 0 | F43: =Data!BC7 -> 0 | K43: =Data!BD7 -> 0 | P43: =Data!BE7 -> 0 | U43: =Data!BF7 -> 0 | Y43: =Data!BG7 -> 0 | AC43: =Data!BH7 -> 0
B44: SAFETY
...

Sheet Data
G1: WELL INFO | Q1: JOB INFO | AB1: DAILY OPS Values | AR1: Cum | BC1: CONSUMABLES | BU1: BOP | CC1: TUBING | CQ1: WFE - Casing -Summary Information - Static | DM1: ACTIVITY TIMES | DU1: Completion Intangible | DX1: Completion Tangible | EE1: PERFORATIONS | FD1: Frac Sum - C#10
G2: Well | H2: Field | I2: Lease | J2: API # | Q2: Contractor | R2: Rig | S2: Comp AFE # | T2: Comp AFE $ | U2: Job Name | AB2: Date | AC2: Report # | AD2: Supervisor | AE2: PBTD TD | AF2: PBTD TVD | AG2: Present Operations | AH2: Activity Planned | AI2: Safety Meeting Topic | AJ2: Rig Phone | AK2: Accidents | AR2: Type | AS2: Weight | AT2: Viscosity | AU2: Formation Loss Daily | AV2: Formation Loss | BC2: Drill Water | BU2: Last BOP Test | BV2: BOP Test Due | CC2: Type | CD2: OD | CE2: ID | CF2: Weight | CG2: Grade | CH2: Btm Pipe MD | CI2: Length | CJ2: Remarks | DF2: C#1 | DM2: Start Time | DN2: End Time | DO2: Duration | DP2: Description | DQ2: Phase | DR2: Activity | DS2: NPT Code | EE2: =MAX(EE4:EE200) -> 0 | EF2: Stage | EG2: Top TD | EH2: Btm TD | EI2: Shot Density | EJ2: EHD | EK2: Phasing | EL2: Perforation Date | FC2: Count | FD2: CPL #1 | FE2: C#27 | FF2: C#6 | FG2: C#8 | FI2: C#7 | FJ2: C#9
BB3: Type | BC3: Daily Received | BD3: Daily Used | BE3: Daily Net | BF3: Cum Rec'd | BG3: Cum Used | BH3: Amt on Hand | CQ3: Casing Type | CR3: Casing ID | CS3: OD | CT3: ID | CU3: Weight | CV3: Grade | CW3: Connection | CX3: Length | CY3: TMD | CZ3: TVD | DA3: Top of Cement | DB3: Date Csg Run | DC3: Time Csg Run | DD3: Date Csg Pulled | DE3: Time Csg Pulled | DF3: Remarks | DU3: Code | DV3: Daily | DW3: Cum | DX3: Code | DY3: Daily | DZ3: Cum | EB3: Daily | EC3: Cum | EE3: Records | EJ3: Hole Size | EQ3: Count | ER3: Perf Zone | ES3: Top MD | ET3: Bottom MD | EU3: Density | EV3: EHD | EW3: Phasing | FC3: Records | FD3: Stage # | FE3: Pump Time | FF3: AVG Slurry Rate | FG3: Max Slurry Rate | FH3: Concatenate | FI3: AVG Treat PSI | FJ3: Max Treat PSI | FK3: Concatenate | FM3: Stage | FN3: Pump Time | FO3: AVG Concat | FP3: Max Concat
G4: FORGE 16A [78]-32 | Q4: Frontier Drilling | R4: Frontier Rig 16 | U4: DFIT | AB4: =IF($AD$7=1,AB13,IF($AD$7=2,AB22,AB31)) -> 44201 | AC4: =IF($AD$7=1,AC13,IF($AD$7=2,AC22,AC31)) -> 2 | AD4: =IF($AD$7=1,AD13,IF($AD$7=2,AD22,AD31)) -> D Winkler, L Swearingen, V Welch | AE4: =IF($AD$7=1,AE13,IF($AD$7=2,AE22,AE31)) -> 0 | AF4: =IF($AD$7=1,AF13,IF($AD$7=2,AF22,AF31)) -> 0 | AG4: =IF($AD$7=1,AG13,IF($AD$7=2,AG22,AG31)) -> TRIP IN HOLE WITH 3 1/2 DRILL PIPE | AH4: =IF($AD$7=1,AH13,IF($AD$7=2,AH22,AH31)) -> DRILL OUT CMT, FLOATS AND CIRCULATE OUT SAND | AI4: =IF($AD$7=1,AI13,IF($AD$7=2,AI22,AI31)) -> NIPPLE UP / NIPPLE DOWN BOP STACK | ... AK4: =IF($AD$7=1,AK13,IF($AD$7=2,AK22,AK31)) -> 0 | AR4: Mud | AS4: 9 | AT4: 55 | AU4: 0 | AV4: 0 | BB4: Fuel | BD4: 1811 | BE4: -1811 | BF4: 13360 | BG4: 3137 | BH4: 10223 | BU4: 44201 | BV4: 44232 | CD4: 3.500 | CE4: 2.764 | CF4: 13.3 | CG4: S-135 | CQ4: Conductor | CR4: 4 | CS4: 20 | CT4: 19 | CU4: 54 | CV4: A53B | CW4: Welded | CX4: 130 | CY4: 130 | CZ4: 130 | DA4: 0 | DB4: 44134 | DM4: 6:00 | DN4: 20:00 | DO4: 14 | DP4: Weld on wellhead as per API specs Nipple up and test BOPE; Annular 250 psi low / 5,000 psi high Blind rams, pipe rams, choke lines, manifold, floor valves, top drive valves 250 psi low / 10,000 psi high Casing 1,500 psi Accumulator function test | DQ4: Well Prep | DR4: Pressure Test BOPs | DU4: -200 | DV4: 0 | DW4: 0 | DX4: -300 | DY4: 0 | DZ4: 0 | EB4: =SUM(DV4:DV100)+SUM(DY4:DY100) -> 52569 | EC4: =SUM(DW4:DW100)+SUM(DZ4:DZ100) -> 52569 | EE4: =IF(AND(EF4<>"",EL4<=$AB$4,COUNTIF(EF5:$EF$200,EF4)=0),MAX($EE$3:EE3)+1,0) -> 0 | EQ4: =IF(EE2=0,"",IF(EE2<9,EE2-EE2+1,EE2-7)) | ER4: =IFERROR(INDEX(EF$4:EF$200,MATCH($EQ4,$EE$4:$EE$200,0)),"") | ES4: =IFERROR(INDEX(EG$4:EG$200,MATCH($EQ4,$EE$4:$EE$200,0)),"") | ET4: =IFERROR(INDEX(EH$4:EH$200,MATCH($EQ4,$EE$4:$EE$200,0)),"") | EU4: =IFERROR(INDEX(EI$4:EI$200,MATCH($EQ4,$EE$4:$EE$200,0)),"") | EV4: =IFERROR(INDEX(EJ$4:EJ$200,MATCH($EQ4,$EE$4:$EE$200,0)),"") | EW4: =IFERROR(INDEX(EK$4:EK$200,MATCH($EQ4,$EE$4:$EE$200,0)),"") | FC4: =COUNTA(FD4:FD105) -> 0 | FH4: =IF(FD4<>"",CONCATENATE(FF4," / ",FI4),"") | FK4: =IF(FD4<>"",CONCATENATE(FG4," / ",FJ4),"") | FM4: =IFERROR(IF($FC$4>8,INDEX(FD$4:FD$105,$FC$4-7),FD4),"") -> 0 | FN4: =IFERROR(IF($FC$4>8,INDEX(FE$4:FE$105,$FC$4-7),FE4),"") -> 0 | FO4: =IFERROR(IF($FC$4>8,INDEX(FH$4:FH$105,$FC$4-7),FH4),"") | FP4: =IFERROR(IF($FC$4>8,INDEX(FK$4:FK$105,$FC$4-7),FK4),"")
BB5: Drill Water | BC5: 314 | BD5: 0 | BE5: 314 | BF5: 314 | BG5: 0 | BH5: 314 | CQ5: Surface | CR5: 1 | CS5: 13.375 | CT5: 12.41 | CU5: 68 | CV5: L-80 | CW5: BTC | CX5: 1631.09 | CY5: 1629 | CZ5: 1629 | DA5: 0 | DB5: 44135 | DM5: 20:00 | DN5: 6:00 | DO5: 10 | DP5: Make up BHA and pick up 3 1/2" drill pipe to 7,300' | DQ5: Well Prep | DR5: Trips | DU5: -201 | DV5: 0 | DW5: 0 | DX5: -301 | DY5: 0 | DZ5: 0 | EE5: =IF(AND(EF5<>"",EL5<=$AB$4,COUNTIF(EF6:$EF$200,EF5)=0),MAX($EE$3:EE4)+1,0) -> 0 | EQ5: =IFERROR(IF(EQ4+1>$EE$2,NA(),EQ4+1),"") | ER5: =IFERROR(INDEX(EF$4:EF$200,MATCH($EQ5,$EE$4:$EE$200,0)),"") | ES5: =IFERROR(INDEX(EG$4:EG$200,MATCH($EQ5,$EE$4:$EE$200,0)),"") | ET5: =IFERROR(INDEX(EH$4:EH$200,MATCH($EQ5,$EE$4:$EE$200,0)),"") | EU5: =IFERROR(INDEX(EI$4:EI$200,MATCH($EQ5,$EE$4:$EE$200,0)),"") | EV5: =IFERROR(INDEX(EJ$4:EJ$200,MATCH($EQ5,$EE$4:$EE$200,0)),"") | EW5: =IFERROR(INDEX(EK$4:EK$200,MATCH($EQ5,$EE$4:$EE$200,0)),"") | FH5: =IF(FD5<>"",CONCATENATE(FF5," / ",FI5),"") | FK5: =IF(FD5<>"",CONCATENATE(FG5," / ",FJ5),"") | FM5: =IFERROR(IF($FC$4>8,INDEX(FD$4:FD$105,$FC$4-6),FD5),"") -> 0 | FN5: =IFERROR(IF($FC$4>8,INDEX(FE$4:FE$105,$FC$4-6),FE5),"") -> 0 | FO5: =IFERROR(IF($FC$4>8,INDEX(FH$4:FH$105,$FC$4-6),FH5),"") | FP5: =IFERROR(IF($FC$4>8,INDEX(FK$4:FK$105,$FC$4-6),FK5),"")
AB6: TMD | AC6: TVD | AD6: DO Active | AE6: Email | CQ6: Intermediate | CR6: 5 | CS6: 9.625 | CT6: 8.75 | CU6: 40 | CV6: HCL-80 | CW6: BTC | CX6: 5110 | CY6: 5110 | CZ6: 5109.18 | DA6: 0 | DB6: 44146 | DU6: -202 | DV6: 38000 | DW6: 38000 | DX6: -302 | DY6: 0 | DZ6: 0 | EE6: =IF(AND(EF6<>"",EL6<=$AB$4,COUNTIF(EF7:$EF$200,EF6)=0),MAX($EE$3:EE5)+1,0) -> 0 | EQ6: =IFERROR(IF(EQ5+1>$EE$2,NA(),EQ5+1),"") | ER6: =IFERROR(INDEX(EF$4:EF$200,MATCH($EQ6,$EE$4:$EE$200,0)),"") | ES6: =IFERROR(INDEX(EG$4:EG$200,MATCH($EQ6,$EE$4:$EE$200,0)),"") | ET6: =IFERROR(INDEX(EH$4:EH$200,MATCH($EQ6,$EE$4:$EE$200,0)),"") | EU6: =IFERROR(INDEX(EI$4:EI$200,MATCH($EQ6,$EE$4:$EE$200,0)),"") | EV6: =IFERROR(INDEX(EJ$4:EJ$200,MATCH($EQ6,$EE$4:$EE$200,0)),"") | EW6: =IFERROR(INDEX(EK$4:EK$200,MATCH($EQ6,$EE$4:$EE$200,0)),"") | FH6: =IF(FD6<>"",CONCATENATE(FF6," / ",FI6),"") | FK6: =IF(FD6<>"",CONCATENATE(FG6," / ",FJ6),"") | FM6: =IFERROR(IF($FC$4>8,INDEX(FD$4:FD$105,$FC$4-5),FD6),"") -> 0 | FN6: =IFERROR(IF($FC$4>8,INDEX(FE$4:FE$105,$FC$4-5),FE6),"") -> 0 | FO6: =IFERROR(IF($FC$4>8,INDEX(FH$4:FH$105,$FC$4-5),FH6),"") | FP6: =IFERROR(IF($FC$4>8,INDEX(FK$4:FK$105,$FC$4-5),FK6),"")
AB7: =IF($AD$7=1,AB16,IF($AD$7=2,AB25,AB34)) -> 10987 | AC7: =IF($AD$7=1,AC16,IF($AD$7=2,AC25,AC34)) -> 8559 | AD7: =IF(AB31="",IF(AB22="",1,2),3) -> 1 | AE7: =IF($AD$7=1,AD16,IF($AD$7=2,AD25,AD34)) -> 0 | CQ7: Production | CR7: 6 | CS7: 7 | CT7: 5.92 | CU7: 38 | CV7: T-95 | CW7: JFELION | CX7: 10769.92 | CY7: 10787 | CZ7: 0 | DB7: 44197 | DU7: -203 | DV7: 1104 | DW7: 1104 | DX7: -303 | DY7: 0 | DZ7: 0 | EE7: =IF(AND(EF7<>"",EL7<=$AB$4,COUNTIF(EF8:$EF$200,EF7)=0),MAX($EE$3:EE6)+1,0) -> 0 | EQ7: =IFERROR(IF(EQ6+1>$EE$2,NA(),EQ6+1),"") | ER7: =IFERROR(INDEX(EF$4:EF$200,MATCH($EQ7,$EE$4:$EE$200,0)),"") | ES7: =IFERROR(INDEX(EG$4:EG$200,MATCH($EQ7,$EE$4:$EE$200,0)),"") | ET7: =IFERROR(INDEX(EH$4:EH$200,MATCH($EQ7,$EE$4:$EE$200,0)),"") | EU7: =IFERROR(INDEX(EI$4:EI$200,MATCH($EQ7,$EE$4:$EE$200,0)),"") | EV7: =IFERROR(INDEX(EJ$4:EJ$200,MATCH($EQ7,$EE$4:$EE$200,0)),"") | EW7: =IFERROR(INDEX(EK$4:EK$200,MATCH($EQ7,$EE$4:$EE$200,0)),"") | FH7: =IF(FD7<>"",CONCATENATE(FF7," / ",FI7),"") | FK7: =IF(FD7<>"",CONCATENATE(FG7," / ",FJ7),"") | FM7: =IFERROR(IF($FC$4>8,INDEX(FD$4:FD$105,$FC$4-4),FD7),"") -> 0 | FN7: =IFERROR(IF($FC$4>8,INDEX(FE$4:FE$105,$FC$4-4),FE7),"") -> 0 | FO7: =IFERROR(IF($FC$4>8,INDEX(FH$4:FH$105,$FC$4-4),FH7),"") | FP7: =IFERROR(IF($FC$4>8,INDEX(FK$4:FK$105,$FC$4-4),FK7),"")
DU8: -204 | DV8: 1100 | DW8: 1100 | DX8: -304 | DY8: 0 | DZ8: 0 | EE8: =IF(AND(EF8<>"",EL8<=$AB$4,COUNTIF(EF9:$EF$200,EF8)=0),MAX($EE$3:EE7)+1,0) -> 0 | EQ8: =IFERROR(IF(EQ7+1>$EE$2,NA(),EQ7+1),"") | ER8: =IFERROR(INDEX(EF$4:EF$200,MATCH($EQ8,$EE$4:$EE$200,0)),"") | ES8: =IFERROR(INDEX(EG$4:EG$200,MATCH($EQ8,$EE$4:$EE$200,0)),"") | ET8: =IFERROR(INDEX(EH$4:EH$200,MATCH($EQ8,$EE$4:$EE$200,0)),"") | EU8: =IFERROR(INDEX(EI$4:EI$200,MATCH($EQ8,$EE$4:$EE$200,0)),"") | EV8: =IFERROR(INDEX(EJ$4:EJ$200,MATCH($EQ8,$EE$4:$EE$200,0)),"") | EW8: =IFERROR(INDEX(EK$4:EK$200,MATCH($EQ8,$EE$4:$EE$200,0)),"") | FH8: =IF(FD8<>"",CONCATENATE(FF8," / ",FI8),"") | FK8: =IF(FD8<>"",CONCATENATE(FG8," / ",FJ8),"") | FM8: =IFERROR(IF($FC$4>8,INDEX(FD$4:FD$105,$FC$4-3),FD8),"") -> 0 | FN8: =IFERROR(IF($FC$4>8,INDEX(FE$4:FE$105,$FC$4-3),FE8),"") -> 0 | FO8: =IFERROR(IF($FC$4>8,INDEX(FH$4:FH$105,$FC$4-3),FH8),"") | FP8: =IFERROR(IF($FC$4>8,INDEX(FK$4:FK$105,$FC$4-3),FK8),"")
DU9: -205 | DV9: 500 | DW9: 500 | DX9: -305 | DY9: 0 | DZ9: 0 | EE9: =IF(AND(EF9<>"",EL9<=$AB$4,COUNTIF(EF10:$EF$200,EF9)=0),MAX($EE$3:EE8)+1,0) -> 0 | EQ9: =IFERROR(IF(EQ8+1>$EE$2,NA(),EQ8+1),"") | ER9: =IFERROR(INDEX(EF$4:EF$200,MATCH($EQ9,$EE$4:$EE$200,0)),"") | ES9: =IFERROR(INDEX(EG$4:EG$200,MATCH($EQ9,$EE$4:$EE$200,0)),"") | ET9: =IFERROR(INDEX(EH$4:EH$200,MATCH($EQ9,$EE$4:$EE$200,0)),"") | EU9: =IFERROR(INDEX(EI$4:EI$200,MATCH($EQ9,$EE$4:$EE$200,0)),"") | EV9: =IFERROR(INDEX(EJ$4:EJ$200,MATCH($EQ9,$EE$4:$EE$200,0)),"") | EW9: =IFERROR(INDEX(EK$4:EK$200,MATCH($EQ9,$EE$4:$EE$200,0)),"") | FH9: =IF(FD9<>"",CONCATENATE(FF9," / ",FI9),"") | FK9: =IF(FD9<>"",CONCATENATE(FG9," / ",FJ9),"") | FM9: =IFERROR(IF($FC$4>8,INDEX(FD$4:FD$105,$FC$4-2),FD9),"") -> 0 | FN9: =IFERROR(IF($FC$4>8,INDEX(FE$4:FE$105,$FC$4-2),FE9),"") -> 0 | FO9: =IFERROR(IF($FC$4>8,INDEX(FH$4:FH$105,$FC$4-2),FH9),"") | FP9: =IFERROR(IF($FC$4>8,INDEX(FK$4:FK$105,$FC$4-2),FK9),"")
AB10: DAILY OPS 1 | DU10: -206 | DV10: 60 | DW10: 60 | DX10: -306 | DY10: 0 | DZ10: 0 | EE10: =IF(AND(EF10<>"",EL10<=$AB$4,COUNTIF(EF11:$EF$200,EF10)=0),MAX($EE$3:EE9)+1,0) -> 0 | EQ10: =IFERROR(IF(EQ9+1>$EE$2,NA(),EQ9+1),"") | ER10: =IFERROR(INDEX(EF$4:EF$200,MATCH($EQ10,$EE$4:$EE$200,0)),"") | ES10: =IFERROR(INDEX(EG$4:EG$200,MATCH($EQ10,$EE$4:$EE$200,0)),"") | ET10: =IFERROR(INDEX(EH$4:EH$200,MATCH($EQ10,$EE$4:$EE$200,0)),"") | EU10: =IFERROR(INDEX(EI$4:EI$200,MATCH($EQ10,$EE$4:$EE$200,0)),"") | EV10: =IFERROR(INDEX(EJ$4:EJ$200,MATCH($EQ10,$EE$4:$EE$200,0)),"") | EW10: =IFERROR(INDEX(EK$4:EK$200,MATCH($EQ10,$EE$4:$EE$200,0)),"") | FH10: =IF(FD10<>"",CONCATENATE(FF10," / ",FI10),"") | FK10: =IF(FD10<>"",CONCATENATE(FG10," / ",FJ10),"") | FM10: =IFERROR(IF($FC$4>8,INDEX(FD$4:FD$105,$FC$4-1),FD10),"") -> 0 | FN10: =IFERROR(IF($FC$4>8,INDEX(FE$4:FE$105,$FC$4-1),FE10),"") -> 0 | FO10: =IFERROR(IF($FC$4>8,INDEX(FH$4:FH$105,$FC$4-1),FH10),"") | FP10: =IFERROR(IF($FC$4>8,INDEX(FK$4:FK$105,$FC$4-1),FK10),"")
AB11: Date | AC11: Report # | AD11: Supervisor | AE11: PBTD TD | AF11: PBTD TVD | AG11: Present Operations | AH11: Activity Planned | AI11: Safety Meeting Topic | AJ11: Rig Phone | AK11: Accidents | DU11: -207 | DV11: 60 | DW11: 60 | DX11: -307 | DY11: 0 | DZ11: 0 | EE11: =IF(AND(EF11<>"",EL11<=$AB$4,COUNTIF(EF12:$EF$200,EF11)=0),MAX($EE$3:EE10)+1,0) -> 0 | EQ11: =IFERROR(IF(EQ10+1>$EE$2,NA(),EQ10+1),"") | ER11: =IFERROR(INDEX(EF$4:EF$200,MATCH($EQ11,$EE$4:$EE$200,0)),"") | ES11: =IFERROR(INDEX(EG$4:EG$200,MATCH($EQ11,$EE$4:$EE$200,0)),"") | ET11: =IFERROR(INDEX(EH$4:EH$200,MATCH($EQ11,$EE$4:$EE$200,0)),"") | EU11: =IFERROR(INDEX(EI$4:EI$200,MATCH($EQ11,$EE$4:$EE$200,0)),"") | EV11: =IFERROR(INDEX(EJ$4:EJ$200,MATCH($EQ11,$EE$4:$EE$200,0)),"") | EW11: =IFERROR(INDEX(EK$4:EK$200,MATCH($EQ11,$EE$4:$EE$200,0)),"") | FH11: =IF(FD11<>"",CONCATENATE(FF11," / ",FI11),"") | FK11: =IF(FD11<>"",CONCATENATE(FG11," / ",FJ11),"") | FM11: =IFERROR(IF($FC$4>8,INDEX(FD$4:FD$105,$FC$4),FD11),"") -> 0 | FN11: =IFERROR(IF($FC$4>8,INDEX(FE$4:FE$105,$FC$4),FE11),"") -> 0 | FO11: =IFERROR(IF($FC$4>8,INDEX(FH$4:FH$105,$FC$4),FH11),"") | FP11: =IFERROR(IF($FC$4>8,INDEX(FK$4:FK$105,$FC$4),FK11),"")
DU12: -208 | DV12: 0 | DW12: 0 | DX12: -308 | DY12: 0 | DZ12: 0 | EE12: =IF(AND(EF12<>"",EL12<=$AB$4,COUNTIF(EF13:$EF$200,EF12)=0),MAX($EE$3:EE11)+1,0) -> 0 | FH12: =IF(FD12<>"",CONCATENATE(FF12," / ",FI12),"") | FK12: =IF(FD12<>"",CONCATENATE(FG12," / ",FJ12),"")
AB13: 44201 | AC13: 2 | AD13: D Winkler, L Swearingen, V Welch | AG13: TRIP IN HOLE WITH 3 1/2 DRILL PIPE | AH13: DRILL OUT CMT, FLOATS AND CIRCULATE OUT SAND | AI13: NIPPLE UP / NIPPLE DOWN BOP STACK | DU13: -209 | DV13: 0 | DW13: 0 | DX13: -309 | DY13: 0 | DZ13: 0 | EE13: =IF(AND(EF13<>"",EL13<=$AB$4,COUNTIF(EF14:$EF$200,EF13)=0),MAX($EE$3:EE12)+1,0) -> 0 | FH13: =IF(FD13<>"",CONCATENATE(FF13," / ",FI13),"") | FK13: =IF(FD13<>"",CONCATENATE(FG13," / ",FJ13),"")
DU14: -210 | DV14: 0 | DW14: 0 | DX14: -310 | DY14: 0 | DZ14: 0 | EE14: =IF(AND(EF14<>"",EL14<=$AB$4,COUNTIF(EF15:$EF$200,EF14)=0),MAX($EE$3:EE13)+1,0) -> 0 | FH14: =IF(FD14<>"",CONCATENATE(FF14," / ",FI14),"") | FK14: =IF(FD14<>"",CONCATENATE(FG14," / ",FJ14),"")
AB15: TMD | AC15: TVD | AD15: Email | DU15: -210B | DV15: 120 | DW15: 120 | DX15: -311 | DY15: 0 | DZ15: 0 | EE15: =IF(AND(EF15<>"",EL15<=$AB$4,COUNTIF(EF16:$EF$200,EF15)=0),MAX($EE$3:EE14)+1,0) -> 0 | FH15: =IF(FD15<>"",CONCATENATE(FF15," / ",FI15),"") | FK15: =IF(FD15<>"",CONCATENATE(FG15," / ",FJ15),"")
AB16: 10987 | AC16: 8559 | DU16: -211 | DV16: 0 | DW16: 0 | DX16: -312 | DY16: 0 | DZ16: 0 | EE16: =IF(AND(EF16<>"",EL16<=$AB$4,COUNTIF(EF17:$EF$200,EF16)=0),MAX($EE$3:EE15)+1,0) -> 0 | FH16: =IF(FD16<>"",CONCATENATE(FF16," / ",FI16),"") | FK16: =IF(FD16<>"",CONCATENATE(FG16," / ",FJ16),"")
DU17: -212 | DV17: 0 | DW17: 0 | DX17: -311 | DY17: 0 | DZ17: 0 | EE17: =IF(AND(EF17<>"",EL17<=$AB$4,COUNTIF(EF18:$EF$200,EF17)=0),MAX($EE$3:EE16)+1,0) -> 0 | FH17: =IF(FD17<>"",CONCATENATE(FF17," / ",FI17),"") | FK17: =IF(FD17<>"",CONCATENATE(FG17," / ",FJ17),"")
DU18: -213 | DV18: 5000 | DW18: 5000 | DX18: -312 | DY18: 0 | DZ18: 0 | EE18: =IF(AND(EF18<>"",EL18<=$AB$4,COUNTIF(EF19:$EF$200,EF18)=0),MAX($EE$3:EE17)+1,0) -> 0 | FH18: =IF(FD18<>"",CONCATENATE(FF18," / ",FI18),"") | FK18: =IF(FD18<>"",CONCATENATE(FG18," / ",FJ18),"")
AB19: DAILY OPS 2 | DU19: -214 | DV19: 0 | DW19: 0 | EE19: =IF(AND(EF19<>"",EL19<=$AB$4,COUNTIF(EF20:$EF$200,EF19)=0),MAX($EE$3:EE18)+1,0) -> 0 | FH19: =IF(FD19<>"",CONCATENATE(FF19," / ",FI19),"") | FK19: =IF(FD19<>"",CONCATENATE(FG19," / ",FJ19),"")
AB20: Date | AC20: Report # | AD20: Supervisor | AE20: PBTD TD | AF20: PBTD TVD | AG20: Present Operations | AH20: Activity Planned | AI20: Safety Meeting Topic | AJ20: Rig Phone | AK20: Accidents | DU20: -215 | DV20: 0 | DW20: 0 | EE20: =IF(AND(EF20<>"",EL20<=$AB$4,COUNTIF(EF21:$EF$200,EF20)=0),MAX($EE$3:EE19)+1,0) -> 0 | FH20: =IF(FD20<>"",CONCATENATE(FF20," / ",FI20),"") | FK20: =IF(FD20<>"",CONCATENATE(FG20," / ",FJ20),"")
DU21: -216 | DV21: 0 | DW21: 0 | EE21: =IF(AND(EF21<>"",EL21<=$AB$4,COUNTIF(EF22:$EF$200,EF21)=0),MAX($EE$3:EE20)+1,0) -> 0 | FH21: =IF(FD21<>"",CONCATENATE(FF21," / ",FI21),"") | FK21: =IF(FD21<>"",CONCATENATE(FG21," / ",FJ21),"")
DU22: -217 | DV22: 0 | DW22: 0 | EE22: =IF(AND(EF22<>"",EL22<=$AB$4,COUNTIF(EF23:$EF$200,EF22)=0),MAX($EE$3:EE21)+1,0) -> 0 | FH22: =IF(FD22<>"",CONCATENATE(FF22," / ",FI22),"") | FK22: =IF(FD22<>"",CONCATENATE(FG22," / ",FJ22),"")
DU23: -218 | DV23: 0 | DW23: 0 | EE23: =IF(AND(EF23<>"",EL23<=$AB$4,COUNTIF(EF24:$EF$200,EF23)=0),MAX($EE$3:EE22)+1,0) -> 0 | FH23: =IF(FD23<>"",CONCATENATE(FF23," / ",FI23),"") | FK23: =IF(FD23<>"",CONCATENATE(FG23," / ",FJ23),"")
AB24: TMD | AC24: TVD | AD24: Email | DU24: -219 | DV24: 0 | DW24: 0 | EE24: =IF(AND(EF24<>"",EL24<=$AB$4,COUNTIF(EF25:$EF$200,EF24)=0),MAX($EE$3:EE23)+1,0) -> 0 | FH24: =IF(FD24<>"",CONCATENATE(FF24," / ",FI24),"") | FK24: =IF(FD24<>"",CONCATENATE(FG24," / ",FJ24),"")
DU25: -220 | DV25: 0 | DW25: 0 | EE25: =IF(AND(EF25<>"",EL25<=$AB$4,COUNTIF(EF26:$EF$200,EF25)=0),MAX($EE$3:EE24)+1,0) -> 0 | FH25: =IF(FD25<>"",CONCATENATE(FF25," / ",FI25),"") | FK25: =IF(FD25<>"",CONCATENATE(FG25," / ",FJ25),"")
DU26: -221 | DV26: 3185 | DW26: 3185 | EE26: =IF(AND(EF26<>"",EL26<=$AB$4,COUNTIF(EF27:$EF$200,EF26)=0),MAX($EE$3:EE25)+1,0) -> 0 | FH26: =IF(FD26<>"",CONCATENATE(FF26," / ",FI26),"") | FK26: =IF(FD26<>"",CONCATENATE(FG26," / ",FJ26),"")
DU27: -221 | DV27: 0 | DW27: 0 | EE27: =IF(AND(EF27<>"",EL27<=$AB$4,COUNTIF(EF28:$EF$200,EF27)=0),MAX($EE$3:EE26)+1,0) -> 0 | FH27: =IF(FD27<>"",CONCATENATE(FF27," / ",FI27),"") | FK27: =IF(FD27<>"",CONCATENATE(FG27," / ",FJ27),"")
AB28: DAILY OPS 3 | DU28: -222 | DV28: 0 | DW28: 0 | EE28: =IF(AND(EF28<>"",EL28<=$AB$4,COUNTIF(EF29:$EF$200,EF28)=0),MAX($EE$3:EE27)+1,0) -> 0 | FH28: =IF(FD28<>"",CONCATENATE(FF28," / ",FI28),"") | FK28: =IF(FD28<>"",CONCATENATE(FG28," / ",FJ28),"")
AB29: Date | AC29: Report # | AD29: Supervisor | AE29: PBTD TD | AF29: PBTD TVD | AG29: Present Operations | AH29: Activity Planned | AI29: Safety Meeting Topic | AJ29: Rig Phone | AK29: Accidents | DU29: -223 | DV29: 0 | DW29: 0 | EE29: =IF(AND(EF29<>"",EL29<=$AB$4,COUNTIF(EF30:$EF$200,EF29)=0),MAX($EE$3:EE28)+1,0) -> 0 | FH29: =IF(FD29<>"",CONCATENATE(FF29," / ",FI29),"") | FK29: =IF(FD29<>"",CONCATENATE(FG29," / ",FJ29),"")
DU30: -224 | DV30: 0 | DW30: 0 | EE30: =IF(AND(EF30<>"",EL30<=$AB$4,COUNTIF(EF31:$EF$200,EF30)=0),MAX($EE$3:EE29)+1,0) -> 0 | FH30: =IF(FD30<>"",CONCATENATE(FF30," / ",FI30),"") | FK30: =IF(FD30<>"",CONCATENATE(FG30," / ",FJ30),"")
DU31: -225A | DV31: 0 | DW31: 0 | EE31: =IF(AND(EF31<>"",EL31<=$AB$4,COUNTIF(EF32:$EF$200,EF31)=0),MAX($EE$3:EE30)+1,0) -> 0 | FH31: =IF(FD31<>"",CONCATENATE(FF31," / ",FI31),"") | FK31: =IF(FD31<>"",CONCATENATE(FG31," / ",FJ31),"")
DU32: -225 | DV32: 0 | DW32: 0 | EE32: =IF(AND(EF32<>"",EL32<=$AB$4,COUNTIF(EF33:$EF$200,EF32)=0),MAX($EE$3:EE31)+1,0) -> 0 | FH32: =IF(FD32<>"",CONCATENATE(FF32," / ",FI32),"") | FK32: =IF(FD32<>"",CONCATENATE(FG32," / ",FJ32),"")
AB33: TMD | AC33: TVD | AD33: Email | DU33: -226 | DV33: 600 | DW33: 600 | EE33: =IF(AND(EF33<>"",EL33<=$AB$4,COUNTIF(EF34:$EF$200,EF33)=0),MAX($EE$3:EE32)+1,0) -> 0 | FH33: =IF(FD33<>"",CONCATENATE(FF33," / ",FI33),"") | FK33: =IF(FD33<>"",CONCATENATE(FG33," / ",FJ33),"")
DU34: -227 | DV34: 0 | DW34: 0 | EE34: =IF(AND(EF34<>"",EL34<=$AB$4,COUNTIF(EF35:$EF$200,EF34)=0),MAX($EE$3:EE33)+1,0) -> 0 | FH34: =IF(FD34<>"",CONCATENATE(FF34," / ",FI34),"") | FK34: =IF(FD34<>"",CONCATENATE(FG34," / ",FJ34),"")
DU35: -228 | DV35: 0 | DW35: 0 | EE35: =IF(AND(EF35<>"",EL35<=$AB$4,COUNTIF(EF36:$EF$200,EF35)=0),MAX($EE$3:EE34)+1,0) -> 0 | FH35: =IF(FD35<>"",CONCATENATE(FF35," / ",FI35),"") | FK35: =IF(FD35<>"",CONCATENATE(FG35," / ",FJ35),"")
DU36: -229 | DV36: 0 | DW36: 0 | EE36: =IF(AND(EF36<>"",EL36<=$AB$4,COUNTIF(EF37:$EF$200,EF36)=0),MAX($EE$3:EE35)+1,0) -> 0 | FH36: =IF(FD36<>"",CONCATENATE(FF36," / ",FI36),"") | FK36: =IF(FD36<>"",CONCATENATE(FG36," / ",FJ36),"")
DU37: -230 | DV37: 0 | DW37: 0 | EE37: =IF(AND(EF37<>"",EL37<=$AB$4,COUNTIF(EF38:$EF$200,EF37)=0),MAX($EE$3:EE36)+1,0) -> 0 | FH37: =IF(FD37<>"",CONCATENATE(FF37," / ",FI37),"") | FK37: =IF(FD37<>"",CONCATENATE(FG37," / ",FJ37),"")
DU38: -232 | DV38: 0 | DW38: 0 | EE38: =IF(AND(EF38<>"",EL38<=$AB$4,COUNTIF(EF39:$EF$200,EF38)=0),MAX($EE$3:EE37)+1,0) -> 0 | FH38: =IF(FD38<>"",CONCATENATE(FF38," / ",FI38),"") | FK38: =IF(FD38<>"",CONCATENATE(FG38," / ",FJ38),"")
DU39: -231 | DV39: 0 | DW39: 0 | EE39: =IF(AND(EF39<>"",EL39<=$AB$4,COUNTIF(EF40:$EF$200,EF39)=0),MAX($EE$3:EE38)+1,0) -> 0 | FH39: =IF(FD39<>"",CONCATENATE(FF39," / ",FI39),"") | FK39: =IF(FD39<>"",CONCATENATE(FG39," / ",FJ39),"")
DU40: -232 | DV40: 0 | DW40: 0 | EE40: =IF(AND(EF40<>"",EL40<=$AB$4,COUNTIF(EF41:$EF$200,EF40)=0),MAX($EE$3:EE39)+1,0) -> 0 | FH40: =IF(FD40<>"",CONCATENATE(FF40," / ",FI40),"") | FK40: =IF(FD40<>"",CONCATENATE(FG40," / ",FJ40),"")
...

Sheet WellEz Log
A1: Date | B1: Name | C1: Comment / Change | D1: Requested By
A2: 42069 | B2: Barrett Fontenot | C2: Update Logo for WFE Standard | D2: Internal
A3: 42108 | B3: Barrett Fontenot | C3: Corrected linking for Casing section | D3: Internal
A4: 42865 | B4: Michael Martin | C4: Updated for new Standard Style Guide | D4: Internal
A5: 42872 | B5: Michael Martin | C5: Update for Daily Ops 1,2,3 | D5: Internal
A6: 43410 | B6: Stephany Acosta | C6: updated consumables from IFE to WFE | D6: Internal
A7: 43549 | B7: Travis Wingerson | C7: Updated 2019 standard: added Frac stages, plus Phase, Activity, and NPT to time log section | D7: Internal
A8: 43683 | B8: Michael Stoklosa | C8: Updated to reflect WFE perf logic | D8: Internal
A9: 43802 | B9: Travis Wingerson | C9: Updated WFE perf logic to prevent duplicate entries from showing up | D9: Internal
A10: 43885 | B10: Travis Wingerson | C10: Updated for standard WFE Perf Fields | D10: Internal
A11: 43915 | B11: Travis Wingerson | C11: Left Justify all text, center justify all numbers / dates for 2020 standard | D11: Internal
A12: 43834 | B12: Garrett Warren | C12: Reformatted report number to general instead of a date | D12: Duane Winkler
